Traceback (most recent call last):
  File "/usr/share/miniconda3/envs/ipyautoui-dev/lib/python3.11/site-packages/jupyter_cache/executors/utils.py", line 58, in single_nb_execution
    executenb(
  File "/usr/share/miniconda3/envs/ipyautoui-dev/lib/python3.11/site-packages/nbclient/client.py", line 1204, in execute
    return NotebookClient(nb=nb, resources=resources, km=km, **kwargs).execute()
           ^^^^^^^^^^^^^^^^^^^^^^^^^^^^^^^^^^^^^^^^^^^^^^^^^^^^^^^^^^^^^^^^^^^^^
  File "/usr/share/miniconda3/envs/ipyautoui-dev/lib/python3.11/site-packages/nbclient/util.py", line 84, in wrapped
    return just_run(coro(*args, **kwargs))
           ^^^^^^^^^^^^^^^^^^^^^^^^^^^^^^^
  File "/usr/share/miniconda3/envs/ipyautoui-dev/lib/python3.11/site-packages/nbclient/util.py", line 62, in just_run
    return loop.run_until_complete(coro)
           ^^^^^^^^^^^^^^^^^^^^^^^^^^^^^
  File "/usr/share/miniconda3/envs/ipyautoui-dev/lib/python3.11/asyncio/base_events.py", line 653, in run_until_complete
    return future.result()
           ^^^^^^^^^^^^^^^
  File "/usr/share/miniconda3/envs/ipyautoui-dev/lib/python3.11/site-packages/nbclient/client.py", line 663, in async_execute
    await self.async_execute_cell(
  File "/usr/share/miniconda3/envs/ipyautoui-dev/lib/python3.11/site-packages/nbclient/client.py", line 965, in async_execute_cell
    await self._check_raise_for_error(cell, cell_index, exec_reply)
  File "/usr/share/miniconda3/envs/ipyautoui-dev/lib/python3.11/site-packages/nbclient/client.py", line 862, in _check_raise_for_error
    raise CellExecutionError.from_cell_and_msg(cell, exec_reply_content)
nbclient.exceptions.CellExecutionError: An error occurred while executing the following cell:
------------------
from ipyautoui.basemodel import file

file(Example(), pathlib.Path("test.json"))
------------------

[0;31m---------------------------------------------------------------------------[0m
[0;31mValidationError[0m                           Traceback (most recent call last)
Cell [0;32mIn[5], line 3[0m
[1;32m      1[0m [38;5;28;01mfrom[39;00m [38;5;21;01mipyautoui[39;00m[38;5;21;01m.[39;00m[38;5;21;01mbasemodel[39;00m [38;5;28;01mimport[39;00m file
[0;32m----> 3[0m file(Example(), pathlib[38;5;241m.[39mPath([38;5;124m"[39m[38;5;124mtest.json[39m[38;5;124m"[39m))

File [0;32m/usr/share/miniconda3/envs/ipyautoui-dev/lib/python3.11/site-packages/pydantic/main.py:164[0m, in [0;36mBaseModel.__init__[0;34m(__pydantic_self__, **data)[0m
[1;32m    162[0m [38;5;66;03m# `__tracebackhide__` tells pytest and some other tools to omit this function from tracebacks[39;00m
[1;32m    163[0m __tracebackhide__ [38;5;241m=[39m [38;5;28;01mTrue[39;00m
[0;32m--> 164[0m __pydantic_self__[38;5;241m.[39m__pydantic_validator__[38;5;241m.[39mvalidate_python(data, self_instance[38;5;241m=[39m__pydantic_self__)

[0;31mValidationError[0m: 1 validation error for Example
sub
  Field required [type=missing, input_value={}, input_type=dict]
    For further information visit https://errors.pydantic.dev/2.5/v/missing
ValidationError: 1 validation error for Example
sub
  Field required [type=missing, input_value={}, input_type=dict]
    For further information visit https://errors.pydantic.dev/2.5/v/missing

