Traceback (most recent call last):
  File "/usr/share/miniconda3/envs/ipyautoui-dev/lib/python3.12/site-packages/jupyter_cache/executors/utils.py", line 58, in single_nb_execution
    executenb(
  File "/usr/share/miniconda3/envs/ipyautoui-dev/lib/python3.12/site-packages/nbclient/client.py", line 1305, in execute
    return NotebookClient(nb=nb, resources=resources, km=km, **kwargs).execute()
           ^^^^^^^^^^^^^^^^^^^^^^^^^^^^^^^^^^^^^^^^^^^^^^^^^^^^^^^^^^^^^^^^^^^^^
  File "/usr/share/miniconda3/envs/ipyautoui-dev/lib/python3.12/site-packages/jupyter_core/utils/__init__.py", line 165, in wrapped
    return loop.run_until_complete(inner)
           ^^^^^^^^^^^^^^^^^^^^^^^^^^^^^^
  File "/usr/share/miniconda3/envs/ipyautoui-dev/lib/python3.12/asyncio/base_events.py", line 687, in run_until_complete
    return future.result()
           ^^^^^^^^^^^^^^^
  File "/usr/share/miniconda3/envs/ipyautoui-dev/lib/python3.12/site-packages/nbclient/client.py", line 705, in async_execute
    await self.async_execute_cell(
  File "/usr/share/miniconda3/envs/ipyautoui-dev/lib/python3.12/site-packages/nbclient/client.py", line 1058, in async_execute_cell
    await self._check_raise_for_error(cell, cell_index, exec_reply)
  File "/usr/share/miniconda3/envs/ipyautoui-dev/lib/python3.12/site-packages/nbclient/client.py", line 914, in _check_raise_for_error
    raise CellExecutionError.from_cell_and_msg(cell, exec_reply_content)
nbclient.exceptions.CellExecutionError: An error occurred while executing the following cell:
------------------
from jsonschema import validate, Draft202012Validator, ErrorTree

# A sample schema, like what we'd get from json.load()
schema = {
    "type" : "object",
    "properties" : {
        "price" : {"type" : "number"},
        "name" : {"type" : "string"},
    },
}

# If no exception is raised by validate(), the instance is valid.
validate(instance={"name" : "Eggs", "price" : 34.99}, schema=schema)

validate(
    instance={"name" : "Eggs", "price" : "Invalid"}, schema=schema,
)      
------------------

----- stderr -----
/tmp/ipykernel_2360/1006366414.py:1: DeprecationWarning: Importing ErrorTree directly from the jsonschema package is deprecated and will become an ImportError. Import it from jsonschema.exceptions instead.
  from jsonschema import validate, Draft202012Validator, ErrorTree
------------------

[0;31m---------------------------------------------------------------------------[0m
[0;31mValidationError[0m                           Traceback (most recent call last)
Cell [0;32mIn[3], line 15[0m
[1;32m     12[0m [38;5;66;03m# If no exception is raised by validate(), the instance is valid.[39;00m
[1;32m     13[0m validate(instance[38;5;241m=[39m{[38;5;124m"[39m[38;5;124mname[39m[38;5;124m"[39m : [38;5;124m"[39m[38;5;124mEggs[39m[38;5;124m"[39m, [38;5;124m"[39m[38;5;124mprice[39m[38;5;124m"[39m : [38;5;241m34.99[39m}, schema[38;5;241m=[39mschema)
[0;32m---> 15[0m validate(
[1;32m     16[0m     instance[38;5;241m=[39m{[38;5;124m"[39m[38;5;124mname[39m[38;5;124m"[39m : [38;5;124m"[39m[38;5;124mEggs[39m[38;5;124m"[39m, [38;5;124m"[39m[38;5;124mprice[39m[38;5;124m"[39m : [38;5;124m"[39m[38;5;124mInvalid[39m[38;5;124m"[39m}, schema[38;5;241m=[39mschema,
[1;32m     17[0m )

File [0;32m/usr/share/miniconda3/envs/ipyautoui-dev/lib/python3.12/site-packages/jsonschema/validators.py:1306[0m, in [0;36mvalidate[0;34m(instance, schema, cls, *args, **kwargs)[0m
[1;32m   1304[0m error [38;5;241m=[39m exceptions[38;5;241m.[39mbest_match(validator[38;5;241m.[39miter_errors(instance))
[1;32m   1305[0m [38;5;28;01mif[39;00m error [38;5;129;01mis[39;00m [38;5;129;01mnot[39;00m [38;5;28;01mNone[39;00m:
[0;32m-> 1306[0m     [38;5;28;01mraise[39;00m error

[0;31mValidationError[0m: 'Invalid' is not of type 'number'

Failed validating 'type' in schema['properties']['price']:
    {'type': 'number'}

On instance['price']:
    'Invalid'

